<?xml version="1.0"?>
<sdf version='1.6'>
  <world name='default'>
    <model name='ground_plane'>
      <static>1</static>
      <link name='link'>
        <collision name='collision'>
          <geometry>
            <plane>
              <normal>0 0 1</normal>
              <size>100 100</size>
            </plane>
          </geometry>
          <surface>
            <friction>
              <ode>
                <mu>100</mu>
                <mu2>50</mu2>
              </ode>
              <torsional>
                <ode/>
              </torsional>
            </friction>
            <contact>
              <ode/>
            </contact>
            <bounce/>
          </surface>
          <max_contacts>10</max_contacts>
        </collision>
        <visual name='visual'>
          <cast_shadows>0</cast_shadows>
          <geometry>
            <plane>
              <normal>0 0 1</normal>
              <size>100 100</size>
            </plane>
          </geometry>
          <material>
            <script>
              <uri>file://media/materials/scripts/gazebo.material</uri>
              <name>Gazebo/Grey</name>
            </script>
          </material>
        </visual>
        <self_collide>0</self_collide>
        <kinematic>0</kinematic>
        <gravity>1</gravity>
      </link>
    </model>
    <light name='sun' type='directional'>
      <cast_shadows>1</cast_shadows>
      <pose frame=''>0 0 10 0 -0 0</pose>
      <diffuse>0.8 0.8 0.8 1</diffuse>
      <specular>0.1 0.1 0.1 1</specular>
      <attenuation>
        <range>1000</range>
        <constant>0.9</constant>
        <linear>0.01</linear>
        <quadratic>0.001</quadratic>
      </attenuation>
      <direction>-0.5 0.5 -1</direction>
    </light>
    <model name='willowgarage'>
      <static>1</static>
      <pose frame=''>-20 -20 0 0 -0 0</pose>
      <link name='walls'>
        <collision name='collision'>
          <geometry>
            <mesh>
              <uri>model://willowgarage/meshes/willowgarage_collision.dae</uri>
              <scale>1 1 1</scale>
            </mesh>
          </geometry>
          <max_contacts>10</max_contacts>
          <surface>
            <contact>
              <ode/>
            </contact>
            <bounce/>
            <friction>
              <torsional>
                <ode/>
              </torsional>
              <ode/>
            </friction>
          </surface>
        </collision>
        <visual name='visual'>
          <geometry>
            <mesh>
              <uri>model://willowgarage/meshes/willowgarage_visual.dae</uri>
              <scale>1 1 1</scale>
            </mesh>
          </geometry>
          <cast_shadows>0</cast_shadows>
        </visual>
        <self_collide>0</self_collide>
        <kinematic>0</kinematic>
        <gravity>1</gravity>
      </link>
    </model>
    <gravity>0 0 -9.8</gravity>
    <magnetic_field>6e-06 2.3e-05 -4.2e-05</magnetic_field>
    <atmosphere type='adiabatic'/>
    <physics name='default_physics' default='0' type='ode'>
      <max_step_size>0.001</max_step_size>
      <real_time_factor>1</real_time_factor>
      <real_time_update_rate>1000</real_time_update_rate>
    </physics>
    <scene>
      <ambient>0.4 0.4 0.4 1</ambient>
      <background>0.7 0.7 0.7 1</background>
      <shadows>1</shadows>
    </scene>
    <spherical_coordinates>
      <surface_model>EARTH_WGS84</surface_model>
      <latitude_deg>0</latitude_deg>
      <longitude_deg>0</longitude_deg>
      <elevation>0</elevation>
      <heading_deg>0</heading_deg>
    </spherical_coordinates>
    <model name='aiv_rosb'>
      <link name='base_footprint'>
        <pose frame=''>0 0 0 0 -0 0</pose>
        <inertial>
          <pose frame=''>-0.020312 -0.00073 0.127241 0 -0 0</pose>
          <mass>168.889</mass>
          <inertia>
            <ixx>4.17633</ixx>
            <ixy>0.0185732</ixy>
            <ixz>-0.0637647</ixz>
            <iyy>5.70931</iyy>
            <iyz>-0.00224554</iyz>
            <izz>7.75891</izz>
          </inertia>
        </inertial>
        <collision name='base_footprint_fixed_joint_lump__base_link_collision'>
          <pose frame=''>0 0 0 0 -0 0</pose>
          <geometry>
            <mesh>
              <scale>1 1 1</scale>
              <uri>/home/nvidia/catkin_ws/src/aiv_finalsh3/meshes/base_link.STL</uri>
            </mesh>
          </geometry>
          <surface>
            <contact>
              <ode/>
            </contact>
            <friction>
              <ode/>
              <torsional>
                <ode/>
              </torsional>
            </friction>
            <bounce/>
          </surface>
          <max_contacts>10</max_contacts>
        </collision>
        <collision name='base_footprint_fixed_joint_lump__hokuyo_link_collision_1'>
          <pose frame=''>0.285 0 0.138 0 -0 0</pose>
          <geometry>
            <mesh>
              <scale>1 1 1</scale>
              <uri>/home/nvidia/catkin_ws/src/aiv_finalsh3/meshes/hokuyo_link.STL</uri>
            </mesh>
          </geometry>
          <surface>
            <contact>
              <ode/>
            </contact>
            <friction>
              <ode/>
              <torsional>
                <ode/>
              </torsional>
            </friction>
            <bounce/>
          </surface>
          <max_contacts>10</max_contacts>
        </collision>
        <visual name='base_footprint_visual'>
          <pose frame=''>0 0 0 0 -0 0</pose>
          <geometry>
            <box>
              <size>0.001 0.001 0.001</size>
            </box>
          </geometry>
          <material>
            <script>
              <name>Gazebo/Green</name>
              <uri>file://media/materials/scripts/gazebo.material</uri>
            </script>
          </material>
        </visual>
        <visual name='base_footprint_fixed_joint_lump__base_link_visual_1'>
          <pose frame=''>0 0 0 0 -0 0</pose>
          <geometry>
            <mesh>
              <scale>1 1 1</scale>
              <uri>/home/nvidia/catkin_ws/src/aiv_finalsh3/meshes/base_link.STL</uri>
            </mesh>
          </geometry>
          <material>
            <script>
              <name>Gazebo/Orange</name>
              <uri>file://media/materials/scripts/gazebo.material</uri>
            </script>
          </material>
        </visual>
        <visual name='base_footprint_fixed_joint_lump__hokuyo_link_visual_2'>
          <pose frame=''>0.285 0 0.138 0 -0 0</pose>
          <geometry>
            <mesh>
              <scale>1 1 1</scale>
              <uri>/home/nvidia/catkin_ws/src/aiv_finalsh3/meshes/hokuyo_link.STL</uri>
            </mesh>
          </geometry>
          <material>
            <script>
              <uri>__default__</uri>
              <name>__default__</name>
            </script>
          </material>
        </visual>
        <velocity_decay/>
        <velocity_decay/>
        <gravity>1</gravity>
        <velocity_decay/>
        <self_collide>0</self_collide>
        <sensor name='head_hokuyo_sensor' type='ray'>
          <visualize>0</visualize>
          <update_rate>40</update_rate>
          <ray>
            <scan>
              <horizontal>
                <samples>720</samples>
                <resolution>1</resolution>
                <min_angle>-1.5708</min_angle>
                <max_angle>1.5708</max_angle>
              </horizontal>
              <vertical>
                <samples>1</samples>
                <min_angle>0</min_angle>
                <max_angle>0</max_angle>
              </vertical>
            </scan>
            <range>
              <min>0.1</min>
              <max>10</max>
              <resolution>0.001</resolution>
            </range>
            <noise>
              <type>gaussian</type>
              <mean>0</mean>
              <stddev>0.01</stddev>
            </noise>
          </ray>
          <plugin name='gazebo_ros_head_hokuyo_controller' filename='libgazebo_ros_laser.so'>
            <topicName>/robot/laser/scan</topicName>
            <frameName>hokuyo_link</frameName>
            <robotNamespace>/</robotNamespace>
          </plugin>
          <pose frame=''>0.285 0 0.138 0 -0 0</pose>
        </sensor>
        <kinematic>0</kinematic>
      </link>
      <link name='right_wheel1'>
        <pose frame=''>0.139897 0.141568 0.045 1.5708 0 3.14159</pose>
        <inertial>
          <pose frame=''>-0 -0 0.048 0 -0 0</pose>
          <mass>1.38941</mass>
          <inertia>
            <ixx>0.00276634</ixx>
            <ixy>-3.38628e-35</ixy>
            <ixz>-6.86661e-20</ixz>
            <iyy>0.00276634</iyy>
            <iyz>-3.00578e-35</iyz>
            <izz>0.00419515</izz>
          </inertia>
        </inertial>
        <collision name='right_wheel1_collision'>
          <pose frame=''>0 0 0 0 -0 0</pose>
          <geometry>
            <mesh>
              <scale>1 1 1</scale>
              <uri>/home/nvidia/catkin_ws/src/aiv_finalsh3/meshes/right_wheel1.STL</uri>
            </mesh>
          </geometry>
          <surface>
            <contact>
              <ode/>
            </contact>
            <friction>
              <ode/>
              <torsional>
                <ode/>
              </torsional>
            </friction>
            <bounce/>
          </surface>
          <max_contacts>10</max_contacts>
        </collision>
        <visual name='right_wheel1_visual'>
          <pose frame=''>0 0 0 0 -0 0</pose>
          <geometry>
            <mesh>
              <scale>1 1 1</scale>
              <uri>/home/nvidia/catkin_ws/src/aiv_finalsh3/meshes/right_wheel1.STL</uri>
            </mesh>
          </geometry>
          <material>
            <script>
              <name>Gazebo/Black</name>
              <uri>file://media/materials/scripts/gazebo.material</uri>
            </script>
          </material>
        </visual>
        <gravity>1</gravity>
        <velocity_decay/>
        <self_collide>0</self_collide>
        <kinematic>0</kinematic>
      </link>
      <joint name='base_to_wheel1' type='revolute'>
        <child>right_wheel1</child>
        <parent>base_footprint</parent>
        <axis>
          <xyz>0 1 0</xyz>
          <limit>
            <lower>-1e+16</lower>
            <upper>1e+16</upper>
          </limit>
          <dynamics>
            <spring_reference>0</spring_reference>
            <spring_stiffness>0</spring_stiffness>
          </dynamics>
          <use_parent_model_frame>1</use_parent_model_frame>
        </axis>
      </joint>
      <link name='left_wheel2'>
        <pose frame=''>0.139897 -0.141724 0.045 1.5708 0 3.14159</pose>
        <inertial>
          <pose frame=''>-0 -0 -0.048 0 -0 0</pose>
          <mass>1.38941</mass>
          <inertia>
            <ixx>0.00276634</ixx>
            <ixy>-1.00531e-35</ixy>
            <ixz>1.00047e-17</ixz>
            <iyy>0.00276634</iyy>
            <iyz>5.47129e-36</iyz>
            <izz>0.00419515</izz>
          </inertia>
        </inertial>
        <collision name='left_wheel2_collision'>
          <pose frame=''>0 0 0 0 -0 0</pose>
          <geometry>
            <mesh>
              <scale>1 1 1</scale>
              <uri>/home/nvidia/catkin_ws/src/aiv_finalsh3/meshes/left_wheel2.STL</uri>
            </mesh>
          </geometry>
          <surface>
            <contact>
              <ode/>
            </contact>
            <friction>
              <ode/>
              <torsional>
                <ode/>
              </torsional>
            </friction>
            <bounce/>
          </surface>
          <max_contacts>10</max_contacts>
        </collision>
        <visual name='left_wheel2_visual'>
          <pose frame=''>0 0 0 0 -0 0</pose>
          <geometry>
            <mesh>
              <scale>1 1 1</scale>
              <uri>/home/nvidia/catkin_ws/src/aiv_finalsh3/meshes/left_wheel2.STL</uri>
            </mesh>
          </geometry>
          <material>
            <script>
              <name>Gazebo/Black</name>
              <uri>file://media/materials/scripts/gazebo.material</uri>
            </script>
          </material>
        </visual>
        <gravity>1</gravity>
        <velocity_decay/>
        <self_collide>0</self_collide>
        <kinematic>0</kinematic>
      </link>
      <joint name='base_to_wheel2' type='revolute'>
        <child>left_wheel2</child>
        <parent>base_footprint</parent>
        <axis>
          <xyz>0 1 0</xyz>
          <limit>
            <lower>-1e+16</lower>
            <upper>1e+16</upper>
          </limit>
          <dynamics>
            <spring_reference>0</spring_reference>
            <spring_stiffness>0</spring_stiffness>
          </dynamics>
          <use_parent_model_frame>1</use_parent_model_frame>
        </axis>
      </joint>
      <link name='left_wheel3'>
        <pose frame=''>-0.139483 -0.141724 0.045 1.5708 0 3.14159</pose>
        <inertial>
          <pose frame=''>-0 0 -0.048 0 -0 0</pose>
          <mass>1.38941</mass>
          <inertia>
            <ixx>0.00276634</ixx>
            <ixy>1.00751e-35</ixy>
            <ixz>1.00723e-17</ixz>
            <iyy>0.00276634</iyy>
            <iyz>4.1151e-35</iyz>
            <izz>0.00419515</izz>
          </inertia>
        </inertial>
        <collision name='left_wheel3_collision'>
          <pose frame=''>0 0 0 0 -0 0</pose>
          <geometry>
            <mesh>
              <scale>1 1 1</scale>
              <uri>/home/nvidia/catkin_ws/src/aiv_finalsh3/meshes/left_wheel3.STL</uri>
            </mesh>
          </geometry>
          <surface>
            <contact>
              <ode/>
            </contact>
            <friction>
              <ode/>
              <torsional>
                <ode/>
              </torsional>
            </friction>
            <bounce/>
          </surface>
          <max_contacts>10</max_contacts>
        </collision>
        <visual name='left_wheel3_visual'>
          <pose frame=''>0 0 0 0 -0 0</pose>
          <geometry>
            <mesh>
              <scale>1 1 1</scale>
              <uri>/home/nvidia/catkin_ws/src/aiv_finalsh3/meshes/left_wheel3.STL</uri>
            </mesh>
          </geometry>
          <material>
            <script>
              <name>Gazebo/Black</name>
              <uri>file://media/materials/scripts/gazebo.material</uri>
            </script>
          </material>
        </visual>
        <gravity>1</gravity>
        <velocity_decay/>
        <self_collide>0</self_collide>
        <kinematic>0</kinematic>
      </link>
      <joint name='base_to_wheel3' type='revolute'>
        <child>left_wheel3</child>
        <parent>base_footprint</parent>
        <axis>
          <xyz>0 1 0</xyz>
          <limit>
            <lower>-1e+16</lower>
            <upper>1e+16</upper>
          </limit>
          <dynamics>
            <spring_reference>0</spring_reference>
            <spring_stiffness>0</spring_stiffness>
          </dynamics>
          <use_parent_model_frame>1</use_parent_model_frame>
        </axis>
      </joint>
      <link name='right_wheel4'>
        <pose frame=''>-0.139483 0.141568 0.045 1.5708 0 3.14159</pose>
        <inertial>
          <pose frame=''>0 -0 0.048 0 -0 0</pose>
          <mass>1.38941</mass>
          <inertia>
            <ixx>0.00276634</ixx>
            <ixy>-1.09847e-38</ixy>
            <ixz>-6.86661e-20</ixz>
            <iyy>0.00276634</iyy>
            <iyz>-8.15263e-36</iyz>
            <izz>0.00419515</izz>
          </inertia>
        </inertial>
        <collision name='right_wheel4_collision'>
          <pose frame=''>0 0 0 0 -0 0</pose>
          <geometry>
            <mesh>
              <scale>1 1 1</scale>
              <uri>/home/nvidia/catkin_ws/src/aiv_finalsh3/meshes/right_wheel4.STL</uri>
            </mesh>
          </geometry>
          <surface>
            <contact>
              <ode/>
            </contact>
            <friction>
              <ode/>
              <torsional>
                <ode/>
              </torsional>
            </friction>
            <bounce/>
          </surface>
          <max_contacts>10</max_contacts>
        </collision>
        <visual name='right_wheel4_visual'>
          <pose frame=''>0 0 0 0 -0 0</pose>
          <geometry>
            <mesh>
              <scale>1 1 1</scale>
              <uri>/home/nvidia/catkin_ws/src/aiv_finalsh3/meshes/right_wheel4.STL</uri>
            </mesh>
          </geometry>
          <material>
            <script>
              <name>Gazebo/Black</name>
              <uri>file://media/materials/scripts/gazebo.material</uri>
            </script>
          </material>
        </visual>
        <gravity>1</gravity>
        <velocity_decay/>
        <self_collide>0</self_collide>
        <kinematic>0</kinematic>
      </link>
      <joint name='base_to_wheel4' type='revolute'>
        <child>right_wheel4</child>
        <parent>base_footprint</parent>
        <axis>
          <xyz>0 1 0</xyz>
          <limit>
            <lower>-1e+16</lower>
            <upper>1e+16</upper>
          </limit>
          <dynamics>
            <spring_reference>0</spring_reference>
            <spring_stiffness>0</spring_stiffness>
          </dynamics>
          <use_parent_model_frame>1</use_parent_model_frame>
        </axis>
      </joint>
      <plugin name='gazebo_ros_control' filename='libgazebo_ros_control.so'>
        <robotNamespace>/robot</robotNamespace>
      </plugin>
      <static>0</static>
      <plugin name='skid_steer_drive_controller' filename='libgazebo_ros_skid_steer_drive.so'>
        <alwaysOn>true</alwaysOn>
        <updateRate>100.0</updateRate>
        <robotNamespace>/</robotNamespace>
        <leftFrontJoint>base_to_wheel1</leftFrontJoint>
        <rightFrontJoint>base_to_wheel2</rightFrontJoint>
        <leftRearJoint>base_to_wheel4</leftRearJoint>
        <rightRearJoint>base_to_wheel3</rightRearJoint>
        <wheelSeparation>1.132</wheelSeparation>
        <wheelDiameter>0.154</wheelDiameter>
        <torque>10</torque>
        <commandTopic>cmd_vel</commandTopic>
        <odometryTopic>odom</odometryTopic>
        <odometryFrame>odom</odometryFrame>
        <robotBaseFrame>base_footprint</robotBaseFrame>
      </plugin>
      <pose frame=''>0 0 0 0 -0 0</pose>
    </model>
    <state world_name='default'>
      <sim_time>21 454000000</sim_time>
      <real_time>40 887880547</real_time>
      <wall_time>1516267975 486314166</wall_time>
      <iterations>21454</iterations>
      <model name='aiv_rosb'>
        <pose frame=''>-0.004344 0.075578 0.031765 0.000351 -0.000144 -0.290739</pose>
        <scale>1 1 1</scale>
        <link name='base_footprint'>
          <pose frame=''>-0.004344 0.075578 0.031765 0.000351 -0.000144 -0.290739</pose>
          <velocity>0.00112 0.004216 -0.005233 0.000765 -0.002581 0.00197</velocity>
          <acceleration>0.003973 -0.000742 -9.42614 -1.03524 0.61934 -0.061154</acceleration>
          <wrench>0.671053 -0.125234 -1591.97 0 -0 0</wrench>
        </link>
        <link name='left_wheel2'>
          <pose frame=''>0.089043 -0.100317 0.076747 1.57064 0.166132 2.85084</pose>
          <velocity>0.001607 0.005043 -0.007961 0.046585 -0.01629 -0.002791</velocity>
          <acceleration>0.263894 1.29288 -20.873 0.458673 -0.506696 2.64865</acceleration>
          <wrench>0.366657 1.79634 -29.0012 0 -0 0</wrench>
        </link>
        <link name='left_wheel3'>
          <pose frame=''>-0.17861 -0.020227 0.076736 1.57066 0.331615 2.85082</pose>
          <velocity>0.001009 0.003831 -0.015961 0.053515 -0.018364 -0.000527</velocity>
          <acceleration>0.388847 0.177302 -27.9899 -2.84019 -0.831642 2.13705</acceleration>
          <wrench>0.540268 0.246345 -38.8895 0 -0 0</wrench>
        </link>
        <link name='right_wheel1'>
          <pose frame=''>0.170255 0.17109 0.076858 1.5707 -0.141382 2.85086</pose>
          <velocity>0.000258 0.004259 -0.010462 0.062095 -0.020933 0.002858</velocity>
          <acceleration>-1.05482 -0.641599 -14.7287 0.552252 0.954451 -2.14242</acceleration>
          <wrench>-1.46558 -0.891445 -20.4642 0 -0 0</wrench>
        </link>
        <link name='right_wheel4'>
          <pose frame=''>-0.097402 0.251178 0.07683 1.57069 0.146577 2.85083</pose>
          <velocity>0.000493 0.003473 -0.014161 0.059567 -0.020176 0.002407</velocity>
          <acceleration>-0.080892 -0.738447 -21.0526 -2.13655 0.458301 -0.367093</acceleration>
          <wrench>-0.112392 -1.02601 -29.2507 0 -0 0</wrench>
        </link>
      </model>
      <model name='ground_plane'>
        <pose frame=''>0 0 0 0 -0 0</pose>
        <scale>1 1 1</scale>
        <link name='link'>
          <pose frame=''>0 0 0 0 -0 0</pose>
          <velocity>0 0 0 0 -0 0</velocity>
          <acceleration>0 0 0 0 -0 0</acceleration>
          <wrench>0 0 0 0 -0 0</wrench>
        </link>
      </model>
      <model name='willowgarage'>
        <pose frame=''>-20 -20 0 0 -0 0</pose>
        <scale>1 1 1</scale>
        <link name='walls'>
          <pose frame=''>-20 -20 0 0 -0 0</pose>
          <velocity>0 0 0 0 -0 0</velocity>
          <acceleration>0 0 0 0 -0 0</acceleration>
          <wrench>0 0 0 0 -0 0</wrench>
        </link>
      </model>
      <light name='sun'>
        <pose frame=''>0 0 10 0 -0 0</pose>
      </light>
    </state>
    <gui fullscreen='0'>
      <camera name='user_camera'>
        <pose frame=''>5 -5 2 0 0.275643 2.35619</pose>
        <view_controller>orbit</view_controller>
        <projection_type>perspective</projection_type>
      </camera>
    </gui>
  </world>
</sdf>
