<?xml version="1.0"?>
<robot
  name="aiv_with_imu">
  <link
    name="base_link">
    <inertial>
      <origin
        xyz="6.30952428266504E-17 -0.00156394179945474 0.129518871317834"
        rpy="0 0 0" />
      <mass
        value="152.136546659951" />
      <inertia
        ixx="4.14561167080813"
        ixy="1.08997913318684E-05"
        ixz="5.85524050648483E-16"
        iyy="5.38628750439474"
        iyz="-0.00487322107567129"
        izz="7.3945608306805" />
    </inertial>
    <visual>
      <origin
        xyz="0 0 0"
        rpy="0 0 0" />
      <geometry>
        <mesh
          filename="package://aiv_with_imu/meshes/base_link.STL" />
      </geometry>
      <material
        name="">
        <color
          rgba="1 1 0 1" />
      </material>
    </visual>
    <collision>
      <origin
        xyz="0 0 0"
        rpy="0 0 0" />
      <geometry>
        <mesh
          filename="package://aiv_with_imu/meshes/base_link.STL" />
      </geometry>
    </collision>
  </link>
  <link
    name="right_wheel1">
    <inertial>
      <origin
        xyz="-1.12293507825711E-12 -4.29115076805431E-13 0.047999999999027"
        rpy="0 0 0" />
      <mass
        value="1.38940851892519" />
      <inertia
        ixx="0.00276634374084104"
        ixy="-3.38627612015008E-35"
        ixz="-6.86661375907486E-20"
        iyy="0.00276634374084104"
        iyz="-3.0057768047017E-35"
        izz="0.00419515021413011" />
    </inertial>
    <visual>
      <origin
        xyz="0 0 0"
        rpy="0 0 0" />
      <geometry>
        <mesh
          filename="package://aiv_with_imu/meshes/right_wheel1.STL" />
      </geometry>
      <material
        name="">
        <color
          rgba="0.792156862745098 0.819607843137255 0.933333333333333 1" />
      </material>
    </visual>
    <collision>
      <origin
        xyz="0 0 0"
        rpy="0 0 0" />
      <geometry>
        <mesh
          filename="package://aiv_with_imu/meshes/right_wheel1.STL" />
      </geometry>
    </collision>
  </link>
  <joint
    name="right_wheel1_joint"
    type="continuous">
    <origin
      xyz="0.139897063904446 0.14156844913427 0.0450000000000102"
      rpy="1.5707963267949 0 3.14159265358979" />
    <parent
      link="base_link" />
    <child
      link="right_wheel1" />
    <axis
      xyz="0 0 1" />
  </joint>
  <link
    name="left_wheel2">
    <inertial>
      <origin
        xyz="-6.23695539658797E-13 -4.61131133278059E-13 -0.0480000000000041"
        rpy="0 0 0" />
      <mass
        value="1.38940851892519" />
      <inertia
        ixx="0.00276634374084104"
        ixy="-2.74081616441698E-35"
        ixz="1.00733666245754E-17"
        iyy="0.00276634374084104"
        iyz="5.47129115782852E-36"
        izz="0.00419515021413011" />
    </inertial>
    <visual>
      <origin
        xyz="0 0 0"
        rpy="0 0 0" />
      <geometry>
        <mesh
          filename="package://aiv_with_imu/meshes/left_wheel2.STL" />
      </geometry>
      <material
        name="">
        <color
          rgba="0.792156862745098 0.819607843137255 0.933333333333333 1" />
      </material>
    </visual>
    <collision>
      <origin
        xyz="0 0 0"
        rpy="0 0 0" />
      <geometry>
        <mesh
          filename="package://aiv_with_imu/meshes/left_wheel2.STL" />
      </geometry>
    </collision>
  </link>
  <joint
    name="left_wheel2_joint"
    type="continuous">
    <origin
      xyz="0.139897063904454 -0.141724083720374 0.0450000000000127"
      rpy="1.5707963267949 0 3.14159265358979" />
    <parent
      link="base_link" />
    <child
      link="left_wheel2" />
    <axis
      xyz="0 0 1" />
  </joint>
  <link
    name="left_wheel3">
    <inertial>
      <origin
        xyz="-6.14869266613027E-13 5.21964416133613E-13 -0.0480000000000104"
        rpy="0 0 0" />
      <mass
        value="1.38940851892519" />
      <inertia
        ixx="0.00276634374084104"
        ixy="2.74301311244905E-35"
        ixz="1.01409598537663E-17"
        iyy="0.00276634374084104"
        iyz="4.03481145000201E-35"
        izz="0.00419515021413011" />
    </inertial>
    <visual>
      <origin
        xyz="0 0 0"
        rpy="0 0 0" />
      <geometry>
        <mesh
          filename="package://aiv_with_imu/meshes/left_wheel3.STL" />
      </geometry>
      <material
        name="">
        <color
          rgba="0.792156862745098 0.819607843137255 0.933333333333333 1" />
      </material>
    </visual>
    <collision>
      <origin
        xyz="0 0 0"
        rpy="0 0 0" />
      <geometry>
        <mesh
          filename="package://aiv_with_imu/meshes/left_wheel3.STL" />
      </geometry>
    </collision>
  </link>
  <joint
    name="left_wheel3_joint"
    type="continuous">
    <origin
      xyz="-0.139482853114889 -0.141724083720375 0.0449999999997022"
      rpy="1.5707963267949 0 3.14159265358979" />
    <parent
      link="base_link" />
    <child
      link="left_wheel3" />
    <axis
      xyz="0 0 1" />
  </joint>
  <link
    name="right_wheel4">
    <inertial>
      <origin
        xyz="6.02129457405454E-13 -4.51590154160186E-13 0.0480000000000162"
        rpy="0 0 0" />
      <mass
        value="1.38940851892519" />
      <inertia
        ixx="0.00276634374084104"
        ixy="-1.09847401603853E-38"
        ixz="-6.86661375907486E-20"
        iyy="0.00276634374084104"
        iyz="-8.15262893040505E-36"
        izz="0.00419515021413011" />
    </inertial>
    <visual>
      <origin
        xyz="0 0 0"
        rpy="0 0 0" />
      <geometry>
        <mesh
          filename="package://aiv_with_imu/meshes/right_wheel4.STL" />
      </geometry>
      <material
        name="">
        <color
          rgba="0.792156862745098 0.819607843137255 0.933333333333333 1" />
      </material>
    </visual>
    <collision>
      <origin
        xyz="0 0 0"
        rpy="0 0 0" />
      <geometry>
        <mesh
          filename="package://aiv_with_imu/meshes/right_wheel4.STL" />
      </geometry>
    </collision>
  </link>
  <joint
    name="right_wheel4_joint"
    type="continuous">
    <origin
      xyz="-0.139482853115031 0.14156844913422 0.0449999999996804"
      rpy="1.5707963267949 0 3.14159265358979" />
    <parent
      link="base_link" />
    <child
      link="right_wheel4" />
    <axis
      xyz="0 0 1" />
  </joint>
  <link
    name="hokuyo_Link_front">
    <inertial>
      <origin
        xyz="-0.000780692813445782 4.15767225386144E-05 -0.00546903856585218"
        rpy="0 0 0" />
      <mass
        value="0.134683421856808" />
      <inertia
        ixx="7.23289314303324E-05"
        ixy="3.07307453427668E-07"
        ixz="-6.60889302500683E-07"
        iyy="7.60198201005056E-05"
        iyz="1.0529750630197E-07"
        izz="4.80658661333251E-05" />
    </inertial>
    <visual>
      <origin
        xyz="0 0 0"
        rpy="0 0 0" />
      <geometry>
        <mesh
          filename="package://aiv_with_imu/meshes/hokuyo_Link_front.STL" />
      </geometry>
      <material
        name="">
        <color
          rgba="0.156862745098039 0.156862745098039 0.156862745098039 1" />
      </material>
    </visual>
    <collision>
      <origin
        xyz="0 0 0"
        rpy="0 0 0" />
      <geometry>
        <mesh
          filename="package://aiv_with_imu/meshes/hokuyo_Link_front.STL" />
      </geometry>
    </collision>
  </link>
  <joint
    name="hokuyo_link_front_joint"
    type="fixed">
    <origin
      xyz="0.285 0 0.138"
      rpy="-3.14159265358979 7.3142651636939E-29 5.15230954324254E-43" />
    <parent
      link="base_link" />
    <child
      link="hokuyo_Link_front" />
    <axis
      xyz="0 0 0" />
  </joint>
  <link
    name="hokuyo_Link_back">
    <inertial>
      <origin
        xyz="-0.000780692813445838 4.15767225385981E-05 -0.00546903856585218"
        rpy="0 0 0" />
      <mass
        value="0.134683421856808" />
      <inertia
        ixx="7.23289314303326E-05"
        ixy="3.07307453427657E-07"
        ixz="-6.60889302500727E-07"
        iyy="7.60198201005058E-05"
        iyz="1.05297506301984E-07"
        izz="4.80658661333252E-05" />
    </inertial>
    <visual>
      <origin
        xyz="0 0 0"
        rpy="0 0 0" />
      <geometry>
        <mesh
          filename="package://aiv_with_imu/meshes/hokuyo_Link_back.STL" />
      </geometry>
      <material
        name="">
        <color
          rgba="0.156862745098039 0.156862745098039 0.156862745098039 1" />
      </material>
    </visual>
    <collision>
      <origin
        xyz="0 0 0"
        rpy="0 0 0" />
      <geometry>
        <mesh
          filename="package://aiv_with_imu/meshes/hokuyo_Link_back.STL" />
      </geometry>
    </collision>
  </link>
  <joint
    name="hokuyo_Link_back_joint"
    type="fixed">
    <origin
      xyz="-0.284660355023666 0 0.138"
      rpy="-3.14159265358979 0 3.14159265358979" />
    <parent
      link="base_link" />
    <child
      link="hokuyo_Link_back" />
    <axis
      xyz="0 0 0" />
  </joint>
  <link
    name="base_imu_link">
    <inertial>
      <origin
        xyz="-1.301E-18 -2.1684E-19 -0.003"
        rpy="0 0 0" />
      <mass
        value="0.010171" />
      <inertia
        ixx="1.1817E-06"
        ixy="-4.2248E-22"
        ixz="-9.2899E-40"
        iyy="1.8241E-06"
        iyz="0"
        izz="2.9448E-06" />
    </inertial>
    <visual>
      <origin
        xyz="0 0 0"
        rpy="0 0 0" />
      <geometry>
        <mesh
          filename="package://aiv_with_imu/meshes/RazorIMU_Link.STL" />
      </geometry>
      <material
        name="">
        <color
          rgba="0.79216 0.81961 0.93333 1" />
      </material>
    </visual>
    <collision>
      <origin
        xyz="0 0 0"
        rpy="0 0 0" />
      <geometry>
        <mesh
          filename="package://aiv_with_imu/meshes/RazorIMU_Link.STL" />
      </geometry>
    </collision>
  </link>
  <joint
    name="base_imu_link_joint"
    type="fixed">
    <origin
      xyz="-0.0011359 -0.0013983 0.156"
      rpy="6.123E-17 0 0" />
    <parent
      link="base_link" />
    <child
      link="base_imu_link" />
    <axis
      xyz="0 0 0" />
  </joint>
</robot>
