<?xml version="1.0"?>
<robot xmlns:xacro="http://www.ros.org/wiki/xacro" 
       xmlns:sensor="http://playerstage.sourceforge.net/gazebo/xmlschema/#sensor"
       xmlns:controller="http://playerstage.sourceforge.net/gazebo/xmlschema/#controller"
       xmlns:interface="http://playerstage.sourceforge.net/gazebo/xmlschema/#interface"
  name="aiv_imu_v2">
 <xacro:macro name="default_inertial" params="mass">
               <inertial>
                       <mass value="${mass}" />
                       <inertia ixx="1.0" ixy="0.0" ixz="0.0"
                                iyy="1.0" iyz="0.0"
                                izz="1.0" />
               </inertial>
	</xacro:macro>

  <link name="base_footprint">
	<visual>
		<geometry>
			<box size="0.001 0.001 0.001"/>
		</geometry>
		<origin rpy="0 0 0" xyz="0 0 0"/>
	</visual>
	<xacro:default_inertial mass="0.0001"/>
  </link>
 <gazebo reference="base_footprint">
		<material>Gazebo/Green</material>
		<turnGravityOff>false</turnGravityOff>
	</gazebo>

   <joint name="base_footprint_joint" type="fixed">
		<origin xyz="0 0 0" rpy="0 0 0"/>
		<parent link="base_footprint" />
		<child link="base_link" />
	</joint>	
  <link
    name="base_link">
    <inertial>
      <origin
        xyz="6.87793448505206E-17 -0.00156394179945474 0.129518871317834"
        rpy="0 0 0" />
      <mass
        value="152.136546659951" />
      <inertia
        ixx="4.14561167080814"
        ixy="1.08997913320005E-05"
        ixz="5.67688924911096E-16"
        iyy="5.38628750439473"
        iyz="-0.00487322107567128"
        izz="7.3945608306805" />
    </inertial>
    <visual>
      <origin
        xyz="0 0 0"
        rpy="0 0 0" />
      <geometry>
        <mesh
          filename="package://aiv_imu_v2/meshes/base_link.STL" />
      </geometry>
      <material
        name="">
        <color
          rgba="1 1 0 1" />
      </material>
    </visual>
    <collision>
      <origin
        xyz="0 0 0"
        rpy="0 0 0" />
      <geometry>
        <mesh
          filename="package://aiv_imu_v2/meshes/base_link.STL" />
      </geometry>
    </collision>
  </link>
  <link
    name="right_wheel1">
    <inertial>
      <origin
        xyz="-1.14991349775551E-12 -4.40446290550511E-13 0.0479999999990037"
        rpy="0 0 0" />
      <mass
        value="1.38940851892519" />
      <inertia
        ixx="0.00276634374084104"
        ixy="-3.38627612015008E-35"
        ixz="-6.86661375907486E-20"
        iyy="0.00276634374084104"
        iyz="-2.98281691521155E-35"
        izz="0.00419515021413011" />
    </inertial>
    <visual>
      <origin
        xyz="0 0 0"
        rpy="0 0 0" />
      <geometry>
        <mesh
          filename="package://aiv_imu_v2/meshes/right_wheel1.STL" />
      </geometry>
      <material
        name="">
        <color
          rgba="0.792156862745098 0.819607843137255 0.933333333333333 1" />
      </material>
    </visual>
    <collision>
      <origin
        xyz="0 0 0"
        rpy="0 0 0" />
      <geometry>
        <mesh
          filename="package://aiv_imu_v2/meshes/right_wheel1.STL" />
      </geometry>
    </collision>
<gazebo reference="right_wheel1">
         <mu1 value="1.0"/>
         <mu2 value="1.0"/>
         <kp  value="10000000.0" />
         <kd  value="1.0" />
         <fdir1 value="1 0 0"/>
	 <material>Gazebo/Black</material>
          <turnGravityOff>false</turnGravityOff> <turnGravityOff>false</turnGravityOff> 
      </gazebo>
  </link>

  <joint
    name="base_to_wheel1"
    type="continuous">
    <origin
      xyz="0.139897063904446 0.14156844913427 0.0450000000000102"
      rpy="1.5707963267949 0 3.14159265358979" />
    <parent
      link="base_link" />
    <child
      link="right_wheel1" />
    <axis
      xyz="0 0 1" />
  </joint>
<transmission name="right_wheel1_joint_trans">
      <type>transmission_interface/SimpleTransmission</type>
      <joint name="base_to_wheel1" />
      <actuator name="right_wheel1_joint_motor">
        <hardwareInterface>EffortJointInterface</hardwareInterface>
        <mechanicalReduction>1</mechanicalReduction>
      </actuator>
    </transmission>
  <link
    name="left_wheel2">
    <inertial>
      <origin
        xyz="-6.38683550491237E-13 -4.73128480837914E-13 -0.0480000000000041"
        rpy="0 0 0" />
      <mass
        value="1.38940851892519" />
      <inertia
        ixx="0.00276634374084104"
        ixy="-2.74081616441698E-35"
        ixz="1.00733666245754E-17"
        iyy="0.00276634374084104"
        iyz="5.43666137255415E-36"
        izz="0.00419515021413011" />
    </inertial>
    <visual>
      <origin
        xyz="0 0 0"
        rpy="0 0 0" />
      <geometry>
        <mesh
          filename="package://aiv_imu_v2/meshes/left_wheel2.STL" />
      </geometry>
      <material
        name="">
        <color
          rgba="0.792156862745098 0.819607843137255 0.933333333333333 1" />
      </material>
    </visual>
    <collision>
      <origin
        xyz="0 0 0"
        rpy="0 0 0" />
      <geometry>
        <mesh
          filename="package://aiv_imu_v2/meshes/left_wheel2.STL" />
      </geometry>
    </collision>
<gazebo reference="left_wheel2">
         <mu1 value="1.0"/>
         <mu2 value="1.0"/>
         <kp  value="10000000.0" />
         <kd  value="1.0" />
         <fdir1 value="1 0 0"/>
	 <material>Gazebo/Black</material>
        <turnGravityOff>false</turnGravityOff> <turnGravityOff>false</turnGravityOff> 
   </gazebo>
  </link>

  <joint
    name="base_to_wheel2"
    type="continuous">
    <origin
      xyz="0.139897063904454 -0.141724083720374 0.0450000000000127"
      rpy="1.5707963267949 0 3.14159265358979" />
    <parent
      link="base_link" />
    <child
      link="left_wheel2" />
    <axis
      xyz="0 0 1" />
  </joint>
<transmission name="left_wheel2_joint_trans">
      <type>transmission_interface/SimpleTransmission</type>
      <joint name="base_to_wheel2" />
      <actuator name="left_wheel2_joint_motor">
        <hardwareInterface>EffortJointInterface</hardwareInterface>
        <mechanicalReduction>1</mechanicalReduction>
      </actuator>
    </transmission>
  <link
    name="left_wheel3">
    <inertial>
      <origin
        xyz="-6.29857277445467E-13 5.33954824799565E-13 -0.0480000000000106"
        rpy="0 0 0" />
      <mass
        value="1.38940851892519" />
      <inertia
        ixx="0.00276634374084104"
        ixy="2.74301311244906E-35"
        ixz="1.01409598537663E-17"
        iyy="0.00276634374084104"
        iyz="4.15831126603387E-35"
        izz="0.00419515021413011" />
    </inertial>
    <visual>
      <origin
        xyz="0 0 0"
        rpy="0 0 0" />
      <geometry>
        <mesh
          filename="package://aiv_imu_v2/meshes/left_wheel3.STL" />
      </geometry>
      <material
        name="">
        <color
          rgba="0.792156862745098 0.819607843137255 0.933333333333333 1" />
      </material>
    </visual>
    <collision>
      <origin
        xyz="0 0 0"
        rpy="0 0 0" />
      <geometry>
        <mesh
          filename="package://aiv_imu_v2/meshes/left_wheel3.STL" />
      </geometry>
    </collision>
<gazebo reference="left_wheel3">
	 <mu1 value="1.0"/>
         <mu2 value="1.0"/>
         <kp  value="10000000.0" />
         <kd  value="1.0" />
         <fdir1 value="1 0 0"/>
	 <material>Gazebo/Black</material>
        <turnGravityOff>false</turnGravityOff> <turnGravityOff>false</turnGravityOff> 
   </gazebo>
  </link>

  <joint
    name="base_to_wheel3"
    type="continuous">
    <origin
      xyz="-0.139482853114889 -0.141724083720375 0.0449999999997022"
      rpy="1.5707963267949 0 3.14159265358979" />
    <parent
      link="base_link" />
    <child
      link="left_wheel3" />
    <axis
      xyz="0 0 1" />
  </joint>
<transmission name="left_wheel3_joint_trans">
      <type>transmission_interface/SimpleTransmission</type>
      <joint name="base_to_wheel3" />
      <actuator name="left_wheel3_joint_motor">
        <hardwareInterface>EffortJointInterface</hardwareInterface>
        <mechanicalReduction>1</mechanicalReduction>
      </actuator>
    </transmission> 
  <link
    name="right_wheel4">
    <inertial>
      <origin
        xyz="6.17117468237893E-13 -4.63573623932234E-13 0.0480000000000164"
        rpy="0 0 0" />
      <mass
        value="1.38940851892519" />
      <inertia
        ixx="0.00276634374084104"
        ixy="-1.09847401603853E-38"
        ixz="-6.86661375907486E-20"
        iyy="0.00276634374084104"
        iyz="-8.15262893040505E-36"
        izz="0.00419515021413011" />
    </inertial>
    <visual>
      <origin
        xyz="0 0 0"
        rpy="0 0 0" />
      <geometry>
        <mesh
          filename="package://aiv_imu_v2/meshes/right_wheel4.STL" />
      </geometry>
      <material
        name="">
        <color
          rgba="0.792156862745098 0.819607843137255 0.933333333333333 1" />
      </material>
    </visual>
    <collision>
      <origin
        xyz="0 0 0"
        rpy="0 0 0" />
      <geometry>
        <mesh
          filename="package://aiv_imu_v2/meshes/right_wheel4.STL" />
      </geometry>
    </collision>
<gazebo reference="right_wheel4">
	 <mu1 value="1.0"/>
         <mu2 value="1.0"/>
         <kp  value="10000000.0" />
         <kd  value="1.0" />
         <fdir1 value="1 0 0"/>
	 <material>Gazebo/Black</material>
        <turnGravityOff>false</turnGravityOff> <turnGravityOff>false</turnGravityOff> 
      </gazebo>
  </link>
  <joint
    name="base_to_wheel4"
    type="continuous">
    <origin
      xyz="-0.139482853115031 0.14156844913422 0.0449999999996804"
      rpy="1.5707963267949 0 3.14159265358979" />
    <parent
      link="base_link" />
    <child
      link="right_wheel4" />
    <axis
      xyz="0 0 1" />
  </joint>
<transmission name="right_wheel4_joint_trans">
      <type>transmission_interface/SimpleTransmission</type>
      <joint name="base_to_wheel4" />
      <actuator name="right_wheel4_joint_motor">
        <hardwareInterface>EffortJointInterface</hardwareInterface>
        <mechanicalReduction>1</mechanicalReduction>
      </actuator>
    </transmission>
  <link
    name="hokuyo_Link_front">
    <inertial>
      <origin
        xyz="-0.000780692813445782 4.15767225386146E-05 -0.00546903856585218"
        rpy="0 0 0" />
      <mass
        value="0.134683421856808" />
      <inertia
        ixx="7.23289314303323E-05"
        ixy="3.0730745342767E-07"
        ixz="-6.60889302500689E-07"
        iyy="7.60198201005056E-05"
        iyz="1.05297506301973E-07"
        izz="4.80658661333251E-05" />
    </inertial>
    <visual>
      <origin
        xyz="0 0 0"
        rpy="0 0 0" />
      <geometry>
        <mesh
          filename="package://aiv_imu_v2/meshes/hokuyo_Link_front.STL" />
      </geometry>
      <material
        name="">
        <color
          rgba="0.156862745098039 0.156862745098039 0.156862745098039 1" />
      </material>
    </visual>
    <collision>
      <origin
        xyz="0 0 0"
        rpy="0 0 0" />
      <geometry>
        <mesh
          filename="package://aiv_imu_v2/meshes/hokuyo_Link_front.STL" />
      </geometry>
    </collision>
  </link>
  <joint
    name="hokuyo_link__front_joint"
    type="fixed">
    <origin
      xyz="0.285 0 0.138"
      rpy="-3.14159265358979 7.3142651636939E-29 5.15230954324254E-43" />
    <parent
      link="base_link" />
    <child
      link="hokuyo_Link_front" />
    <axis
      xyz="0 0 0" />
  </joint>
  <link
    name="hokuyo_Link_back">
    <inertial>
      <origin
        xyz="-0.000780692813445838 4.15767225385962E-05 -0.00546903856585218"
        rpy="0 0 0" />
      <mass
        value="0.134683421856808" />
      <inertia
        ixx="7.23289314303326E-05"
        ixy="3.0730745342766E-07"
        ixz="-6.60889302500727E-07"
        iyy="7.60198201005058E-05"
        iyz="1.05297506301981E-07"
        izz="4.80658661333252E-05" />
    </inertial>
    <visual>
      <origin
        xyz="0 0 0"
        rpy="0 0 0" />
      <geometry>
        <mesh
          filename="package://aiv_imu_v2/meshes/hokuyo_Link_back.STL" />
      </geometry>
      <material
        name="">
        <color
          rgba="0.156862745098039 0.156862745098039 0.156862745098039 1" />
      </material>
    </visual>
    <collision>
      <origin
        xyz="0 0 0"
        rpy="0 0 0" />
      <geometry>
        <mesh
          filename="package://aiv_imu_v2/meshes/hokuyo_Link_back.STL" />
      </geometry>
    </collision>
  </link>
  <joint
    name="hokuyo_Link_back_joint"
    type="fixed">
    <origin
      xyz="-0.284660355023666 0 0.138"
      rpy="-3.14159265358979 0 3.14159265358979" />
    <parent
      link="base_link" />
    <child
      link="hokuyo_Link_back" />
    <axis
      xyz="0 0 0" />
  </joint>
  <link
    name="base_imu_link">
    <inertial>
      <origin
        xyz="-1.30104260698261E-18 2.16840434497101E-19 0.003"
        rpy="0 0 0" />
      <mass
        value="0.0101714973637686" />
      <inertia
        ixx="1.18169580250659E-06"
        ixy="4.22479333968885E-22"
        ixz="1.79377087379717E-39"
        iyy="1.82413615455415E-06"
        iyz="0"
        izz="2.94480297287813E-06" />
    </inertial>
    <visual>
      <origin
        xyz="0 0 0"
        rpy="0 0 0" />
      <geometry>
        <mesh
          filename="package://aiv_imu_v2/meshes/base_imu_link.STL" />
      </geometry>
      <material
        name="">
        <color
          rgba="0.792156862745098 0.819607843137255 0.933333333333333 1" />
      </material>
    </visual>
    <collision>
      <origin
        xyz="0 0 0"
        rpy="0 0 0" />
      <geometry>
        <mesh
          filename="package://aiv_imu_v2/meshes/base_imu_link.STL" />
      </geometry>
    </collision>
  </link>
  <joint
    name="base_imu_link_Joint"
    type="fixed">
    <origin
      xyz="-0.00113592298461554 -0.00139829930856522 0.156"
      rpy="-3.14159265358979 0 0" />
    <parent
      link="base_link" />
    <child
      link="base_imu_link" />
    <axis
      xyz="0 0 0" />
  </joint>
</robot>
